[0m19:53:59.575752 [debug] [MainThread]: Sending event: {'category': 'dbt', 'action': 'invocation', 'label': 'start', 'context': [<snowplow_tracker.self_describing_json.SelfDescribingJson object at 0x000001990E7EFED0>, <snowplow_tracker.self_describing_json.SelfDescribingJson object at 0x000001990E596010>, <snowplow_tracker.self_describing_json.SelfDescribingJson object at 0x000001990E7ECC10>]}


============================== 19:53:59.630350 | a5321e1d-e313-4047-bbb3-72ab2249d660 ==============================
[0m19:53:59.630350 [info ] [MainThread]: Running with dbt=1.9.3
[0m19:53:59.631364 [debug] [MainThread]: running dbt with arguments {'printer_width': '80', 'indirect_selection': 'eager', 'write_json': 'True', 'log_cache_events': 'False', 'partial_parse': 'True', 'cache_selected_only': 'False', 'warn_error': 'None', 'debug': 'False', 'fail_fast': 'False', 'log_path': 'logs', 'version_check': 'True', 'profiles_dir': 'C:\\Users\\ndiaga.beye\\.dbt', 'use_colors': 'True', 'use_experimental_parser': 'False', 'empty': 'None', 'quiet': 'False', 'no_print': 'None', 'log_format': 'default', 'invocation_command': 'dbt init projet_dbt', 'introspect': 'True', 'static_parser': 'True', 'target_path': 'None', 'warn_error_options': 'WarnErrorOptions(include=[], exclude=[])', 'send_anonymous_usage_stats': 'True'}
[0m19:54:00.147604 [debug] [MainThread]: Starter project path: C:\Users\ndiaga.beye\AppData\Local\Packages\PythonSoftwareFoundation.Python.3.11_qbz5n2kfra8p0\LocalCache\local-packages\Python311\site-packages\dbt\include\starter_project
[0m19:54:00.365505 [info ] [MainThread]: 
Your new dbt project "projet_dbt" was created!

For more information on how to configure the profiles.yml file,
please consult the dbt documentation here:

  https://docs.getdbt.com/docs/configure-your-profile

One more thing:

Need help? Don't hesitate to reach out to us via GitHub issues or on Slack:

  https://community.getdbt.com/

Happy modeling!

[0m19:54:00.368020 [info ] [MainThread]: Setting up your profile.
[0m20:24:13.985611 [error] [MainThread]: Encountered an error:

[0m20:24:14.129735 [error] [MainThread]: Traceback (most recent call last):
  File "C:\Users\ndiaga.beye\AppData\Local\Packages\PythonSoftwareFoundation.Python.3.11_qbz5n2kfra8p0\LocalCache\local-packages\Python311\site-packages\dbt\cli\requires.py", line 153, in wrapper
    result, success = func(*args, **kwargs)
                      ^^^^^^^^^^^^^^^^^^^^^
  File "C:\Users\ndiaga.beye\AppData\Local\Packages\PythonSoftwareFoundation.Python.3.11_qbz5n2kfra8p0\LocalCache\local-packages\Python311\site-packages\dbt\cli\requires.py", line 103, in wrapper
    return func(*args, **kwargs)
           ^^^^^^^^^^^^^^^^^^^^^
  File "C:\Users\ndiaga.beye\AppData\Local\Packages\PythonSoftwareFoundation.Python.3.11_qbz5n2kfra8p0\LocalCache\local-packages\Python311\site-packages\dbt\cli\main.py", line 477, in init
    results = task.run()
              ^^^^^^^^^^
  File "C:\Users\ndiaga.beye\AppData\Local\Packages\PythonSoftwareFoundation.Python.3.11_qbz5n2kfra8p0\LocalCache\local-packages\Python311\site-packages\dbt\task\init.py", line 346, in run
    self.setup_profile(profile_name)
  File "C:\Users\ndiaga.beye\AppData\Local\Packages\PythonSoftwareFoundation.Python.3.11_qbz5n2kfra8p0\LocalCache\local-packages\Python311\site-packages\dbt\task\init.py", line 261, in setup_profile
    adapter = self.ask_for_adapter_choice()
              ^^^^^^^^^^^^^^^^^^^^^^^^^^^^^
  File "C:\Users\ndiaga.beye\AppData\Local\Packages\PythonSoftwareFoundation.Python.3.11_qbz5n2kfra8p0\LocalCache\local-packages\Python311\site-packages\dbt\task\init.py", line 242, in ask_for_adapter_choice
    numeric_choice = click.prompt(prompt_msg, type=click.INT)
                     ^^^^^^^^^^^^^^^^^^^^^^^^^^^^^^^^^^^^^^^^
  File "C:\Users\ndiaga.beye\AppData\Local\Packages\PythonSoftwareFoundation.Python.3.11_qbz5n2kfra8p0\LocalCache\local-packages\Python311\site-packages\click\termui.py", line 164, in prompt
    value = prompt_func(prompt)
            ^^^^^^^^^^^^^^^^^^^
  File "C:\Users\ndiaga.beye\AppData\Local\Packages\PythonSoftwareFoundation.Python.3.11_qbz5n2kfra8p0\LocalCache\local-packages\Python311\site-packages\click\termui.py", line 147, in prompt_func
    raise Abort() from None
click.exceptions.Abort

[0m20:24:14.149280 [debug] [MainThread]: Command `dbt init` failed at 20:24:14.146019 after 1814.84 seconds
[0m20:24:14.157568 [debug] [MainThread]: Sending event: {'category': 'dbt', 'action': 'invocation', 'label': 'end', 'context': [<snowplow_tracker.self_describing_json.SelfDescribingJson object at 0x000001990E7EC450>, <snowplow_tracker.self_describing_json.SelfDescribingJson object at 0x00000199089872D0>, <snowplow_tracker.self_describing_json.SelfDescribingJson object at 0x000001990E808610>]}
[0m20:24:14.162355 [debug] [MainThread]: Flushing usage events
[0m20:24:15.230237 [debug] [MainThread]: An error was encountered while trying to flush usage events
